<?xml version="1.0"?>
<robot name="robot" xmlns:xacro="http://www.ros.org/wiki/xacro">
    <xacro:property name="props" value="${load_yaml('..//yaml/urdf.yaml')}"/>
    <xacro:property name="size" value="${load_yaml('..//yaml/sizeparams.yaml')}"/>
 
    <material name="red">
        <color rgba="1 0.0 0.0 1"/>
    </material>

    <material name="green">
        <color rgba="0.0 1.0 0.0 1.0"/>
    </material>

    <material name="blue">
        <color rgba="0 0 1 1"/>
    </material>

    <material name="white"> 
        <color rgba="1 1 1 1"/>
    </material>

    <link name="base_link">
        <visual>
            <geometry>
                <cylinder length="${size['base_height']}" radius="${size['base_width']}"/>
            </geometry>
            <origin xyz="0 0 0"/>
            <material name="blue"/>
        </visual>
    </link>

    <link name="link_1">
        <visual>
            <geometry>
                <box size="${size['linki1_width']} ${size['linki1_width']} ${props['i1']['l_len']}"/>
            </geometry>
            <origin xyz="0 0 -0.25" rpy="0 0 0"/>
            <material name="red"/>
        </visual>
    </link>

    <link name="link_2">
        <visual>
            <geometry>
                <box size="${size['linki2_width']} ${size['linki2_width']} 0.5"/>
            </geometry>
            <origin xyz="-0.25 0 0" rpy="0 1.57 0"/>
            <material name="green"/>
        </visual>
    </link>

    <link name="link_3">
        <visual>
            <geometry>
                <box size="${size['linki3_width']} ${size['linki3_width']} ${size['linki3_height']}"/>
            </geometry>
            <origin xyz="0.1 -0 0" rpy="0 1.57 0"/>
            <material name="white"/>
        </visual>
    </link>


    <joint name="base_link1" type="prismatic">
        <parent link="base_link"/>
        <child link="link_1"/>
        <origin xyz="${props['i1']['j_xyz']}" rpy="${props['i1']['j_rpy']}"/>
        <axis xyz="0 0 1"/>
        <limit effort="1000.0" lower="-0.2" upper="0.2" velocity="0.5"/>
    </joint>

    <joint name="link1_link2" type="revolute">
        <parent link="link_1"/>
        <child link="link_2"/>
        <origin xyz="${props['i2']['j_xyz']}" rpy="${props['i2']['j_rpy']}"/>
        <axis xyz="0 0 1"/>
        <limit effort="1000.0" lower="-1.57" upper="1.57" velocity="0.5"/>
    </joint>

    <joint name="link2_link3" type="revolute">
        <parent link="link_2"/>
        <child link="link_3"/>
        <origin xyz="${props['i3']['j_xyz']}" rpy="${props['i3']['j_rpy']}"/>
        <limit effort="1000.0" lower="-1" upper="1" velocity="0.5"/>
        <axis xyz="0 0 1"/>
    </joint>

</robot>